Workbook
Name Atividade_Administrativa: PARAMETROS!$AE$19:$AL$19
Name Banco_Questões: PARAMETROS!$AE$20:$AJ$20
Name Conselho_Editorial: PARAMETROS!$AE$15:$AL$15
Name Conselho_Profissional: PARAMETROS!$AE$24:$AI$24
Name CPA: PARAMETROS!$AE$25:$AI$25
Name Disciplinas_Digitais: PARAMETROS!$AE$28:$AJ$28
Name Elaborar_Extensão: PARAMETROS!$AE$13:$AR$13
Name Formação_Docente: PARAMETROS!$AE$21:$AM$21
Name NDE: PARAMETROS!$AE$26:$AG$26
Name Organização_ENADE: PARAMETROS!$AE$22:$AU$22
Name Organização_Eventos: PARAMETROS!$AE$23:$AM$23
Name Orientar_Estagio: PARAMETROS!$AE$6:$AL$6
Name Orientar_Extensão: PARAMETROS!$AE$14:$AL$14
Name Orientar_IC: PARAMETROS!$AE$16:$AI$16
Name Orientar_Monitoria: PARAMETROS!$AE$8:$AJ$8
Name Orientar_Preceptoria: PARAMETROS!$AE$7:$AJ$7
Name Orientar_TCC: PARAMETROS!$AE$9:$AL$9
Name Participação_Núcleo: PARAMETROS!$AE$27:$AI$27
Name Planejamento_Aula: PARAMETROS!$AE$4:$AH$4
Name Planejamento_Disciplina: PARAMETROS!$AE$5:$AL$5
Name Produção_Gravação: PARAMETROS!$AE$10:$AM$10
Name Produção_Livros: PARAMETROS!$AE$11:$AM$11
Name Produção_Roteiro_Video: PARAMETROS!$AE$12:$AM$12
Name Projeto_Inovação: PARAMETROS!$AE$17:$AM$17
Name Projeto_Pesquisa: PARAMETROS!$AE$18:$AM$18

Sheet PARAMETROS
A1: NOME | B1: CHAPA | C1: CH SEMANAL | D1: CH LETIVA | E1: CH NÃO-LETIVA | F1: EQUIPE (RH) | G1: CPF | H1: STATUS | I1: CARGO | K1: MÓDULO | L1: ORDEM | M1: DIA | N1: HORÁRIOS | U1: ID | V1: NATUREZA | W1: GRUPO ATIVIDADE | X1: ATOR | Y1: ATIVIDADE | Z1: CLASSE DE ANÁLISE | AA1: GLOSSÁRIO | AB1: TIPO ATIVIDADE | AC1: OBSERVAÇÃO | AD1: CHAVE | AE1: CH MIN VAL | AF1: CH MAX VAL
AY2: {=IFERROR( FILTRAR( PARAMETROS!$AE$4:$AR$99, (PARAMETROS!$Y$4:$Y$99='PREENCHIMENTO|NÃO-LETIVAS'!X4)* (PARAMETROS!$AE$4:$AR$99<>"") ), "")}
A3: ADRIANA DOS SANTOS SOUZA CREVELIN | B3: 012009006172 | C3: 12 | D3: =IF(I3="PROFESSOR REGENTE",IF(C3=40,C3*0.5,IF(C3>11,C3*0.75,C3)),IF(I3="PROFESSOR DE ENSINO SUPERIOR EAD",IF(C3=40,4,2),0)) -> 9 | E3: =IF(OR(I3="PROFESSOR REGENTE",I3="PROFESSOR DE ENSINO SUPERIOR PRESENCIAL"),C3-D3,IF(C3=40,12,6)) -> 3 | F3: JULIANA MORAES DA SILVA | G3: 29290419865 | H3: ATIVO | I3: PROFESSOR REGENTE | K3: 51|2026 | L3: 1 | M3: 2 - Segunda | N3: 19:00 às 20:30
A4: ADRIANO PARRAS MENEGATTI | B4: 012009004349 | C4: 20 | D4: =IF(I4="PROFESSOR REGENTE",IF(C4=40,C4*0.5,IF(C4>11,C4*0.75,C4)),IF(I4="PROFESSOR DE ENSINO SUPERIOR EAD",IF(C4=40,4,2),0)) -> 2 | E4: =IF(OR(I4="PROFESSOR REGENTE",I4="PROFESSOR DE ENSINO SUPERIOR PRESENCIAL"),C4-D4,IF(C4=40,12,6)) -> 6 | F4: JULIANA MORAES DA SILVA | G4: 08784034939 | H4: ATIVO | I4: PROFESSOR DE ENSINO SUPERIOR EAD | K4: 52|2026 | L4: 2 | M4: 3 - Terça | N4: 20:40 às 22:10 | U4: 1 | V4: Ensino | W4: Aulas | X4: Professor EAD, Professor Regente | Y4: Planejamento da Aula | Z4: Atividades de Ensino | AA4: Organizar os materiais e recursos didáticos para ministração da aula, bem como elaborar o portfólio da disciplina. | AB4: Horas não letivas | AC4: Deve ser feito registro por disciplina | AD4: Planejamento_Aula | AE4: 0 | AF4: 0.5 | AG4: =AF4+0.25 -> 0.75 | AH4: 1
A5: ADRIANO RUY MATSUO | B5: 012009003801 | C5: 40 | D5: =IF(I5="PROFESSOR REGENTE",IF(C5=40,C5*0.5,IF(C5>11,C5*0.75,C5)),IF(I5="PROFESSOR DE ENSINO SUPERIOR EAD",IF(C5=40,4,2),0)) -> 4 | E5: =IF(OR(I5="PROFESSOR REGENTE",I5="PROFESSOR DE ENSINO SUPERIOR PRESENCIAL"),C5-D5,IF(C5=40,12,6)) -> 12 | F5: JULIANA MORAES DA SILVA | G5: 05088387970 | H5: ATIVO | I5: PROFESSOR DE ENSINO SUPERIOR EAD | K5: 53|2026 | L5: ESTENDIDA | M5: 4 - Quarta | U5: 2 | V5: Ensino | W5: Aulas | X5: Professor EAD, Professor Regente | Y5: Planejamento da Disciplina | Z5: Atividades de Ensino | AA5: Atualizar ementa, bibliografia e plano de ensino, conforme deliberação do NDE. Elaborar o plano de ação da disciplina. Elaborar os slides padrão para a aula ao vivo. Realizar o apoio e orientação aos Tutores de Prática e aos Professores Mediadores vinculados às suas disciplinas. | AB5: Horas não letivas | AC5: Deve ser feito registro por disciplina | AD5: Planejamento_Disciplina | AE5: 0 | AF5: 0.5 | AG5: =AF5+0.25 -> 0.75 | AH5: 1 | AI5: 1.25 | AJ5: 1.5 | AK5: 1.75 | AL5: 2
A6: ADRIELE ANDRADE CEOLA | B6: 012009003713 | C6: 20 | D6: =IF(I6="PROFESSOR REGENTE",IF(C6=40,C6*0.5,IF(C6>11,C6*0.75,C6)),IF(I6="PROFESSOR DE ENSINO SUPERIOR EAD",IF(C6=40,4,2),0)) -> 2 | E6: =IF(OR(I6="PROFESSOR REGENTE",I6="PROFESSOR DE ENSINO SUPERIOR PRESENCIAL"),C6-D6,IF(C6=40,12,6)) -> 6 | F6: JULIANA MORAES DA SILVA | G6: 09015334919 | H6: ATIVO | I6: PROFESSOR DE ENSINO SUPERIOR EAD | K6: 54|2026 | M6: 5 - Quinta | U6: 3 | V6: Ensino | W6: Orientação | X6: Professor EAD, Professor Regente, Professor Mediador | Y6: Orientar Estágio Curricular (Obrigatório) | Z6: Estágio curricular | AA6: Orientar e acompanhar as atividades referentes ao Estágio Curricular junto aos estudantes e supervisores/preceptores. Realizar plantões mensais com os estudantes, gravar tutoriais, participação em seminário, elaborar e cadastrar propostas avaliativas. | AB6: Horas não letivas | AC6: Deve ser feito registro por disciplina e turma | AD6: Orientar_Estagio | AE6: 0 | AF6: 0.5 | AG6: =AF6+0.25 -> 0.75 | AH6: 1 | AI6: 1.25 | AJ6: 1.5 | AK6: 1.75 | AL6: 2
A7: ALEXANDRE LUIS PONCE MARTINS | B7: 012009004457 | C7: 20 | D7: =IF(I7="PROFESSOR REGENTE",IF(C7=40,C7*0.5,IF(C7>11,C7*0.75,C7)),IF(I7="PROFESSOR DE ENSINO SUPERIOR EAD",IF(C7=40,4,2),0)) -> 2 | E7: =IF(OR(I7="PROFESSOR REGENTE",I7="PROFESSOR DE ENSINO SUPERIOR PRESENCIAL"),C7-D7,IF(C7=40,12,6)) -> 6 | F7: JULIANA MORAES DA SILVA | G7: 06923731950 | H7: ATIVO | I7: PROFESSOR DE ENSINO SUPERIOR EAD | M7: 6 - Sexta | U7: 4 | V7: Ensino | W7: Orientação | X7: Professor EAD, Professor Regente, Professor Regente de Polo | Y7: Orientar Preceptoria e Supervisão (Saúde/Educação) | Z7: Estágio curricular | AA7: Preceptoria e supervisão em estágios curriculares obrigatórios. | AB7: Horas não letivas | AD7: Orientar_Preceptoria | AE7: 0 | AF7: 1 | AG7: =AF7+0.25 -> 1.25 | AH7: 1.5 | AI7: 1.75 | AJ7: 2
A8: ALINE DOS SANTOS PRETO DE SOUZA | B8: 012009005709 | C8: 20 | D8: =IF(I8="PROFESSOR REGENTE",IF(C8=40,C8*0.5,IF(C8>11,C8*0.75,C8)),IF(I8="PROFESSOR DE ENSINO SUPERIOR EAD",IF(C8=40,4,2),0)) -> 2 | E8: =IF(OR(I8="PROFESSOR REGENTE",I8="PROFESSOR DE ENSINO SUPERIOR PRESENCIAL"),C8-D8,IF(C8=40,12,6)) -> 6 | F8: JULIANA MORAES DA SILVA | G8: 00780598954 | H8: ATIVO | I8: PROFESSOR DE ENSINO SUPERIOR EAD | U8: 5 | V8: Ensino | W8: Orientação | X8: Professor EAD, Professor Regente, Professor Mediador | Y8: Orientar Projeto de Monitoria | Z8: Orient. Ensino - Demais | AA8: Orientar Projetos de Monitoria, a partir dos dados enviados pelo Núcleo de Monitoria. Produzir nivelamento, oficinas e projetos de ensino. | AB8: Horas não letivas | AD8: Orientar_Monitoria | AE8: 0 | AF8: 1 | AG8: =AF8+0.25 -> 1.25 | AH8: 1.5 | AI8: 1.75 | AJ8: 2
A9: AMANDA FERREIRA GUIMARAES | B9: 012009006176 | C9: 12 | D9: =IF(I9="PROFESSOR REGENTE",IF(C9=40,C9*0.5,IF(C9>11,C9*0.75,C9)),IF(I9="PROFESSOR DE ENSINO SUPERIOR EAD",IF(C9=40,4,2),0)) -> 9 | E9: =IF(OR(I9="PROFESSOR REGENTE",I9="PROFESSOR DE ENSINO SUPERIOR PRESENCIAL"),C9-D9,IF(C9=40,12,6)) -> 3 | F9: JULIANA MORAES DA SILVA | G9: 34572496870 | H9: ADMISSÃO PROX.MÊS | I9: PROFESSOR REGENTE | U9: 6 | V9: Ensino | W9: Orientação | X9: Professor EAD, Professor Regente, Professor Mediador | Y9: Orientar Trabalho de Conclusão de Curso (TCC) | Z9: TCC/Monografia | AA9: Orientar e acompanhar as atividades referentes ao TCC/Monografia junto aos estudantes. Realizar plantões periodicos e/ou bancas com os estudantes. | AB9: Horas não letivas | AC9: Deve ser feito registro por turma | AD9: Orientar_TCC | AE9: 0 | AF9: 0.5 | AG9: =AF9+0.25 -> 0.75 | AH9: 1 | AI9: 1.25 | AJ9: 1.5 | AK9: 1.75 | AL9: 2
A10: ANA CLAUDIA DE ABREU | B10: 012009004231 | C10: 20 | D10: =IF(I10="PROFESSOR REGENTE",IF(C10=40,C10*0.5,IF(C10>11,C10*0.75,C10)),IF(I10="PROFESSOR DE ENSINO SUPERIOR EAD",IF(C10=40,4,2),0)) -> 2 | E10: =IF(OR(I10="PROFESSOR REGENTE",I10="PROFESSOR DE ENSINO SUPERIOR PRESENCIAL"),C10-D10,IF(C10=40,12,6)) -> 6 | F10: JULIANA MORAES DA SILVA | G10: 07853006942 | H10: ATIVO | I10: PROFESSOR DE ENSINO SUPERIOR EAD | U10: 7 | V10: Ensino | W10: Produção de material didático | X10: Professor EAD, Professor Regente | Y10: Produção de material didático - Gravações | Z10: Gravações | AA10: Produzir materiais gravados para as disciplinas, tais como: gravação de aulas conceituais, gravação de aulas em pontes de feriados, gravação de autoatividades, gravação de podcasts, gravação de cápsulas de conhecimento, gravação de atividades práticas, entre outros. | AB10: Horas não letivas | AC10: Deve ser feito registro por disciplina | AD10: Produção_Gravação | AE10: 0 | AF10: 0.25 | AG10: =AF10+0.25 -> 0.5 | AH10: 0.75 | AI10: 1 | AJ10: 1.25 | AK10: 1.5 | AL10: 1.75 | AM10: 2
A11: ANA ELISA LAVEZO | B11: 012009003540 | C11: 40 | D11: =IF(I11="PROFESSOR REGENTE",IF(C11=40,C11*0.5,IF(C11>11,C11*0.75,C11)),IF(I11="PROFESSOR DE ENSINO SUPERIOR EAD",IF(C11=40,4,2),0)) -> 4 | E11: =IF(OR(I11="PROFESSOR REGENTE",I11="PROFESSOR DE ENSINO SUPERIOR PRESENCIAL"),C11-D11,IF(C11=40,12,6)) -> 12 | F11: JULIANA MORAES DA SILVA | G11: 02651880914 | H11: ATIVO | I11: PROFESSOR DE ENSINO SUPERIOR EAD | U11: 8 | V11: Ensino | W11: Produção de material didático | X11: Professor EAD, Professor Regente | Y11: Produção de material didático - Livros e Outros | Z11: Gestão da disciplina | AA11: Revisar livro da disciplina. Produzir, revisar e atualizar materiais didáticos, tais como: trilhas de aprendizagens, materiais complementares, diretrizes, e-books, manuais, objetos de aprendizagem, entre outros relativos às disciplinas. | AB11: Horas não letivas | AC11: Deve ser feito registro por disciplina | AD11: Produção_Livros | AE11: 0 | AF11: 0.25 | AG11: =AF11+0.25 -> 0.5 | AH11: 0.75 | AI11: 1 | AJ11: 1.25 | AK11: 1.5 | AL11: 1.75 | AM11: 2
A12: ANA LUCIA SALES DE LIMA | B12: 012009003558 | C12: 20 | D12: =IF(I12="PROFESSOR REGENTE",IF(C12=40,C12*0.5,IF(C12>11,C12*0.75,C12)),IF(I12="PROFESSOR DE ENSINO SUPERIOR EAD",IF(C12=40,4,2),0)) -> 2 | E12: =IF(OR(I12="PROFESSOR REGENTE",I12="PROFESSOR DE ENSINO SUPERIOR PRESENCIAL"),C12-D12,IF(C12=40,12,6)) -> 6 | F12: JULIANA MORAES DA SILVA | G12: 04130621980 | H12: ATIVO | I12: PROFESSOR DE ENSINO SUPERIOR EAD | U12: 9 | V12: Ensino | W12: Produção de material didático | X12: Professor EAD, Professor Regente | Y12: Produção de material didático - Roteiro de Vídeos | Z12: Elaboração de roteiros de vídeos | AA12: Elaborar roteiros/materiais de apoio para as gravações dos vídeos, tais como: aulas conceituais, aulas em pontes de feriados, autoatividades, podcasts, cápsulas de conhecimento, materiais para redes sociais, entre outros. | AB12: Horas não letivas | AC12: Deve ser feito registro por disciplina | AD12: Produção_Roteiro_Video | AE12: 0 | AF12: 0.25 | AG12: =AF12+0.25 -> 0.5 | AH12: 0.75 | AI12: 1 | AJ12: 1.25 | AK12: 1.5 | AL12: 1.75 | AM12: 2
A13: ANA PAULA CAVALCANTE LIMAO DA SILVA | B13: 012009004350 | C13: 20 | D13: =IF(I13="PROFESSOR REGENTE",IF(C13=40,C13*0.5,IF(C13>11,C13*0.75,C13)),IF(I13="PROFESSOR DE ENSINO SUPERIOR EAD",IF(C13=40,4,2),0)) -> 2 | E13: =IF(OR(I13="PROFESSOR REGENTE",I13="PROFESSOR DE ENSINO SUPERIOR PRESENCIAL"),C13-D13,IF(C13=40,12,6)) -> 6 | F13: JULIANA MORAES DA SILVA | G13: 00951182927 | H13: ATIVO | I13: PROFESSOR DE ENSINO SUPERIOR EAD | U13: 10 | V13: Extensão | W13: Organização e Acompanhamento | X13: Professor EAD, Professor Regente, Professor Mediador | Y13: Elaborar Projeto de Extensão | Z13: Extensão | AA13: Elaborar Projeto de Extensão de acordo com as premissas estabelecidas e mediante aprovações necessárias dentro da BU. | AB13: Horas não letivas | AC13: Deve ser feito registro por projeto | AD13: Elaborar_Extensão | AE13: 0 | AF13: 1 | AG13: =AF13+0.25 -> 1.25 | AH13: 1.5 | AI13: 1.75 | AJ13: 2 | AK13: 2.25 | AL13: 2.5 | AM13: 2.75 | AN13: 3 | AO13: 3.25 | AP13: 3.5 | AQ13: 3.75 | AR13: 4
A14: ANDERSON DOUGLAS DA SILVA | B14: 012009006177 | C14: 12 | D14: =IF(I14="PROFESSOR REGENTE",IF(C14=40,C14*0.5,IF(C14>11,C14*0.75,C14)),IF(I14="PROFESSOR DE ENSINO SUPERIOR EAD",IF(C14=40,4,2),0)) -> 9 | E14: =IF(OR(I14="PROFESSOR REGENTE",I14="PROFESSOR DE ENSINO SUPERIOR PRESENCIAL"),C14-D14,IF(C14=40,12,6)) -> 3 | F14: JULIANA MORAES DA SILVA | G14: 34254592876 | H14: ADMISSÃO PROX.MÊS | I14: PROFESSOR REGENTE | U14: 11 | V14: Extensão | W14: Organização e Acompanhamento | X14: Professor EAD, Professor Regente, Professor Mediador | Y14: Orientar Projeto de Extensão | Z14: Extensão | AA14: Orientar e acompanhar as atividades referentes à Extensão junto aos estudantes. Realizar plantões mensais com os estudantes. | AB14: Horas não letivas | AC14: Deve ser feito registro por projeto | AD14: Orientar_Extensão | AE14: 0 | AF14: 0.25 | AG14: =AF14+0.25 -> 0.5 | AH14: 0.75 | AI14: 1 | AJ14: 1.5 | AK14: 1.75 | AL14: 2
A15: ANDERSON KATSUMI MIYATAKE | B15: 012009003470 | C15: 40 | D15: =IF(I15="PROFESSOR REGENTE",IF(C15=40,C15*0.5,IF(C15>11,C15*0.75,C15)),IF(I15="PROFESSOR DE ENSINO SUPERIOR EAD",IF(C15=40,4,2),0)) -> 4 | E15: =IF(OR(I15="PROFESSOR REGENTE",I15="PROFESSOR DE ENSINO SUPERIOR PRESENCIAL"),C15-D15,IF(C15=40,12,6)) -> 12 | F15: JULIANA MORAES DA SILVA | G15: 34064839846 | H15: ATIVO | I15: PROFESSOR DE ENSINO SUPERIOR EAD | U15: 12 | V15: Pesquisa | W15: Orientação Pesquisa | X15: Professor EAD, Professor Regente, Professor Mediador | Y15: Conselho editorial | Z15: Orient.IC/TI | AA15: Compor e atuar junto ao conselho editorial das revistas institucionais. | AB15: Horas não letivas | AD15: Conselho_Editorial | AE15: 0 | AF15: 0.5 | AG15: =AF15+0.25 -> 0.75 | AH15: 1 | AI15: 1.25 | AJ15: 1.5 | AK15: 1.75 | AL15: 2
A16: ANDRESSA MARTINS DIAS FERREIRA | B16: 012009005339 | C16: 40 | D16: =IF(I16="PROFESSOR REGENTE",IF(C16=40,C16*0.5,IF(C16>11,C16*0.75,C16)),IF(I16="PROFESSOR DE ENSINO SUPERIOR EAD",IF(C16=40,4,2),0)) -> 4 | E16: =IF(OR(I16="PROFESSOR REGENTE",I16="PROFESSOR DE ENSINO SUPERIOR PRESENCIAL"),C16-D16,IF(C16=40,12,6)) -> 12 | F16: JULIANA MORAES DA SILVA | G16: 07256864990 | H16: ATIVO | I16: PROFESSOR DE ENSINO SUPERIOR EAD | U16: 13 | V16: Pesquisa | W16: Orientação Pesquisa | X16: Professor EAD, Professor Regente, Professor Mediador | Y16: Orientação de Iniciação Científica | Z16: Orient.IC/TI | AA16: Orientar estudantes de graduação em projetos de Iniciação Científica, promovendo a formação acadêmica por meio da participação em atividades investigativas, bem como orientar e organizar artigos para publicação em eventos e revistas. | AB16: Horas não letivas | AC16: Deve ser feito registro por estudante | AD16: Orientar_IC | AE16: 0 | AF16: 0.25 | AG16: =AF16+0.25 -> 0.5 | AH16: 0.75 | AI16: 1
A17: ANGELA FERREIRA DE LIMA PIZZAIA | B17: 012009004467 | C17: 40 | D17: =IF(I17="PROFESSOR REGENTE",IF(C17=40,C17*0.5,IF(C17>11,C17*0.75,C17)),IF(I17="PROFESSOR DE ENSINO SUPERIOR EAD",IF(C17=40,4,2),0)) -> 4 | E17: =IF(OR(I17="PROFESSOR REGENTE",I17="PROFESSOR DE ENSINO SUPERIOR PRESENCIAL"),C17-D17,IF(C17=40,12,6)) -> 12 | F17: JULIANA MORAES DA SILVA | G17: 93494599904 | H17: ATIVO | I17: PROFESSOR DE ENSINO SUPERIOR EAD | U17: 14 | V17: Pesquisa | W17: Orientação Pesquisa | X17: Coordenador de Curso, Professor EAD, Professor Regente, Professor Mediador | Y17: Projeto de Inovação | Z17: UA com Base Regulatória | AA17: Desenvolver ou participar de iniciativas voltadas à criação, testagem ou implementação de soluções inovadoras. | AB17: Horas não letivas | AC17: Deve ser feito registro por projeto | AD17: Projeto_Inovação | AE17: 0 | AF17: 0.25 | AG17: =AF17+0.25 -> 0.5 | AH17: 0.75 | AI17: 1 | AJ17: 1.25 | AK17: 1.5 | AL17: 1.75 | AM17: 2
A18: ANTONIO ALVES PEREIRA JUNIOR | B18: 012009006181 | C18: 12 | D18: =IF(I18="PROFESSOR REGENTE",IF(C18=40,C18*0.5,IF(C18>11,C18*0.75,C18)),IF(I18="PROFESSOR DE ENSINO SUPERIOR EAD",IF(C18=40,4,2),0)) -> 9 | E18: =IF(OR(I18="PROFESSOR REGENTE",I18="PROFESSOR DE ENSINO SUPERIOR PRESENCIAL"),C18-D18,IF(C18=40,12,6)) -> 3 | F18: JULIANA MORAES DA SILVA | G18: 06235685947 | H18: ADMISSÃO PROX.MÊS | I18: PROFESSOR REGENTE | U18: 15 | V18: Pesquisa | W18: Orientação Pesquisa | X18: Professor EAD, Professor Regente, Professor Mediador | Y18: Projeto de Pesquisa | Z18: UA com Base Regulatória | AA18: Participar ou coordenar projetos de pesquisa científica vinculados à instituição, com objetivos definidos, cronograma, metodologia e registro formal junto à área responsável. A atividade pode envolver coleta e análise de dados, elaboração de relatórios, artigos e participação em eventos científicos. | AB18: Horas não letivas | AC18: Deve ser feito registro por projeto | AD18: Projeto_Pesquisa | AE18: 0 | AF18: 0.25 | AG18: =AF18+0.25 -> 0.5 | AH18: 0.75 | AI18: 1 | AJ18: 1.25 | AK18: 1.5 | AL18: 1.75 | AM18: 2
A19: AUGUSTO JOAO STRICTAR MORETTO JUNIOR | B19: 012009003638 | C19: 20 | D19: =IF(I19="PROFESSOR REGENTE",IF(C19=40,C19*0.5,IF(C19>11,C19*0.75,C19)),IF(I19="PROFESSOR DE ENSINO SUPERIOR EAD",IF(C19=40,4,2),0)) -> 2 | E19: =IF(OR(I19="PROFESSOR REGENTE",I19="PROFESSOR DE ENSINO SUPERIOR PRESENCIAL"),C19-D19,IF(C19=40,12,6)) -> 6 | F19: JULIANA MORAES DA SILVA | G19: 07999576905 | H19: ATIVO | I19: PROFESSOR DE ENSINO SUPERIOR EAD | U19: 16 | V19: Planejamento | W19: Administrativas | X19: Professor EAD, Professor Regente, Professor Mediador | Y19: Atividades Administrativas/Gestão | Z19: Administrativas | AA19: Realizar atividades administrativas relacionadas ao curso, de acordo com orientação da coordenação. Por exemplo: ajustar e revisar atas, acompanhar e coletar assinaturas nas atas, acompanhar e elaborar portfólios de atividades do curso, participar de avaliações de MEC, entre outros. | AB19: Horas não letivas | AD19: Atividade_Administrativa | AE19: 0 | AF19: 0.5 | AG19: =AF19+0.25 -> 0.75 | AH19: 1 | AI19: 1.25 | AJ19: 1.5 | AK19: 1.75 | AL19: 2
A20: BARBARA LETICIA DA SILVA GUEDES DE MOURA | B20: 012009005453 | C20: 20 | D20: =IF(I20="PROFESSOR REGENTE",IF(C20=40,C20*0.5,IF(C20>11,C20*0.75,C20)),IF(I20="PROFESSOR DE ENSINO SUPERIOR EAD",IF(C20=40,4,2),0)) -> 2 | E20: =IF(OR(I20="PROFESSOR REGENTE",I20="PROFESSOR DE ENSINO SUPERIOR PRESENCIAL"),C20-D20,IF(C20=40,12,6)) -> 6 | F20: GISLAINE CARDOSO DE SOUZA FIAES | G20: 06229448947 | H20: ATIVO | I20: PROFESSOR DE ENSINO SUPERIOR EAD | U20: 17 | V20: Planejamento | W20: Gestão Acadêmica | X20: Professor EAD, Professor Regente, Professor Mediador | Y20: Banco de Questões | Z20: Gestão da disciplina | AA20: Elaborar, cadastrar, revisar e cancelar questões de acordo com as premissas estabelecidas para cada BU | AB20: Horas não letivas | AC20: Deve ser feito registro por disciplina | AD20: Banco_Questões | AE20: 0 | AF20: 1 | AG20: =AF20+0.25 -> 1.25 | AH20: 1.5 | AI20: 1.75 | AJ20: 2
A21: BIANCA PAIXAO IZALBERTI | B21: 012009004310 | C21: 40 | D21: =IF(I21="PROFESSOR REGENTE",IF(C21=40,C21*0.5,IF(C21>11,C21*0.75,C21)),IF(I21="PROFESSOR DE ENSINO SUPERIOR EAD",IF(C21=40,4,2),0)) -> 4 | E21: =IF(OR(I21="PROFESSOR REGENTE",I21="PROFESSOR DE ENSINO SUPERIOR PRESENCIAL"),C21-D21,IF(C21=40,12,6)) -> 12 | F21: JULIANA MORAES DA SILVA | G21: 06937762933 | H21: ATIVO | I21: PROFESSOR DE ENSINO SUPERIOR EAD | U21: 18 | V21: Planejamento | W21: Gestão Acadêmica | X21: Coordenador de Curso, Professor EAD, Professor Regente, Professor Mediador | Y21: Formação Docente | Z21: Formação continuada | AA21: Participar de programas, cursos, oficinas, reuniões, treinamentos ou eventos institucionais voltados ao desenvolvimento pedagógico, tecnológico ou científico, com o objetivo de aprimorar a atuação docente e alinhar práticas ao projeto educacional da instituição. | AB21: Horas não letivas | AD21: Formação_Docente | AE21: 0 | AF21: 0.25 | AG21: =AF21+0.25 -> 0.5 | AH21: 0.75 | AI21: 1 | AJ21: 1.25 | AK21: 1.5 | AL21: 1.75 | AM21: 2
A22: BRUNA MAYARA ROLDAO FERREIRA | B22: 012009005987 | C22: 20 | D22: =IF(I22="PROFESSOR REGENTE",IF(C22=40,C22*0.5,IF(C22>11,C22*0.75,C22)),IF(I22="PROFESSOR DE ENSINO SUPERIOR EAD",IF(C22=40,4,2),0)) -> 2 | E22: =IF(OR(I22="PROFESSOR REGENTE",I22="PROFESSOR DE ENSINO SUPERIOR PRESENCIAL"),C22-D22,IF(C22=40,12,6)) -> 6 | F22: JULIANA MORAES DA SILVA | G22: 06489968916 | H22: ATIVO | I22: PROFESSOR DE ENSINO SUPERIOR EAD | U22: 19 | V22: Planejamento | W22: Gestão Acadêmica | X22: Professor EAD, Professor Regente | Y22: Organização do ENADE | Z22: Gestão pedagógica | AA22: Atuar na organização de processos relativos ao ENADE. Preencher questionário de avaliação prática dos estudantes (licenciaturas). | AB22: Horas não letivas | AD22: Organização_ENADE | AE22: 0 | AF22: 0.25 | AG22: =AF22+0.25 -> 0.5 | AH22: 0.75 | AI22: 1 | AJ22: 1.25 | AK22: 1.5 | AL22: 1.75 | AM22: 2 | AN22: 2.25 | AO22: 2.5 | AP22: 2.75 | AQ22: 3 | AR22: 3.25 | AS22: 3.5 | AT22: 3.75 | AU22: 4
A23: CARINA SERON DA FONSECA | B23: 012009006205 | C23: 12 | D23: =IF(I23="PROFESSOR REGENTE",IF(C23=40,C23*0.5,IF(C23>11,C23*0.75,C23)),IF(I23="PROFESSOR DE ENSINO SUPERIOR EAD",IF(C23=40,4,2),0)) -> 9 | E23: =IF(OR(I23="PROFESSOR REGENTE",I23="PROFESSOR DE ENSINO SUPERIOR PRESENCIAL"),C23-D23,IF(C23=40,12,6)) -> 3 | F23: JULIANA MORAES DA SILVA | G23: 06982676994 | H23: ADMISSÃO PROX.MÊS | I23: PROFESSOR REGENTE | U23: 20 | V23: Planejamento | W23: Organização de Eventos Acadêmicos | X23: Professor EAD, Professor Regente, Professor Mediador | Y23: Organização de Eventos Acadêmicos | Z23: Eventos | AA23: Organizar e participar de eventos acadêmicos de interesse da BU. | AB23: Horas não letivas | AD23: Organização_Eventos | AE23: 0 | AF23: 0.25 | AG23: =AF23+0.25 -> 0.5 | AH23: 0.75 | AI23: 1 | AJ23: 1.25 | AK23: 1.5 | AL23: 1.75 | AM23: 2
A24: CARLA FABIANA DE ANDRADE GONCALVES IORI | B24: 012009003517 | C24: 40 | D24: =IF(I24="PROFESSOR REGENTE",IF(C24=40,C24*0.5,IF(C24>11,C24*0.75,C24)),IF(I24="PROFESSOR DE ENSINO SUPERIOR EAD",IF(C24=40,4,2),0)) -> 4 | E24: =IF(OR(I24="PROFESSOR REGENTE",I24="PROFESSOR DE ENSINO SUPERIOR PRESENCIAL"),C24-D24,IF(C24=40,12,6)) -> 12 | F24: JULIANA MORAES DA SILVA | G24: 03652555996 | H24: ATIVO | I24: PROFESSOR DE ENSINO SUPERIOR EAD | U24: 21 | V24: Planejamento | W24: Unidade Acadêmica Com Base Regulatória | X24: Coordenador de Curso, Professor EAD, Professor Regente, Professor Mediador | Y24: Conselho Profissional | Z24: UA com Base Regulatória | AA24: Participar da composição de conselho profissional (CAU, CREA, CRA, COREN, entre outros). | AB24: Horas não letivas | AC24: Deve ser feito registro por conselho | AD24: Conselho_Profissional | AE24: 0 | AF24: 0.25 | AG24: =AF24+0.25 -> 0.5 | AH24: 0.75 | AI24: 1
A25: CAROLINE PREVIATO SOUZA | B25: 012009004488 | C25: 40 | D25: =IF(I25="PROFESSOR REGENTE",IF(C25=40,C25*0.5,IF(C25>11,C25*0.75,C25)),IF(I25="PROFESSOR DE ENSINO SUPERIOR EAD",IF(C25=40,4,2),0)) -> 4 | E25: =IF(OR(I25="PROFESSOR REGENTE",I25="PROFESSOR DE ENSINO SUPERIOR PRESENCIAL"),C25-D25,IF(C25=40,12,6)) -> 12 | F25: JULIANA MORAES DA SILVA | G25: 06374431952 | H25: ATIVO | I25: PROFESSOR DE ENSINO SUPERIOR EAD | U25: 22 | V25: Planejamento | W25: Unidade Acadêmica Com Base Regulatória | X25: Coordenador de Curso, Professor EAD, Professor Regente, Professor Mediador | Y25: CPA - Comissão Própria de Avaliação | Z25: UA com Base Regulatória | AA25: Participar da Comissão Própria de Avaliação - CPA - de acordo com a Lei 10.861/2004 (SINAES). | AB25: Horas não letivas | AC25: Considera-se que CPA organiza reuniões de trabalho um vez ao mês com duração de uma ou duas horas no máximo | AD25: CPA | AE25: 0 | AF25: 0.25 | AG25: =AF25+0.25 -> 0.5 | AH25: 0.75 | AI25: 1
A26: CAROLINE WOLF TRENTINI SCHIPFER | B26: 012009006209 | C26: 12 | D26: =IF(I26="PROFESSOR REGENTE",IF(C26=40,C26*0.5,IF(C26>11,C26*0.75,C26)),IF(I26="PROFESSOR DE ENSINO SUPERIOR EAD",IF(C26=40,4,2),0)) -> 9 | E26: =IF(OR(I26="PROFESSOR REGENTE",I26="PROFESSOR DE ENSINO SUPERIOR PRESENCIAL"),C26-D26,IF(C26=40,12,6)) -> 3 | F26: JULIANA MORAES DA SILVA | G26: 05209839982 | H26: ADMISSÃO PROX.MÊS | I26: PROFESSOR REGENTE | U26: 23 | V26: Planejamento | W26: Unidade Acadêmica Com Base Regulatória | X26: Coordenador de Curso, Professor EAD, Professor Regente, Professor Mediador | Y26: NDE - Núcleo Docente Estruturante | Z26: UA com Base Regulatória | AA26: Compor o Núcleo Docente Estruturante (NDE) dos cursos de graduação. Estas atividades devem ser exercidas apenas por Professores TI ou TP. Atribuição deve ser encaminhada via ofício e aprovação da Pro-Reitoria da BU. | AB26: Horas não letivas | AC26: Considera-se um encontro mensal de uma hora ou duas no máximo para o NDE. Participar do NDE não consiste apenas em participar das reuniões. Há aprovações de materiais, ementas, entre outros. | AD26: NDE | AE26: 0 | AF26: 0.25 | AG26: =AF26+0.25 -> 0.5
A27: CLAUDETE CRISTINA IWATA | B27: 012009003393 | C27: 40 | D27: =IF(I27="PROFESSOR REGENTE",IF(C27=40,C27*0.5,IF(C27>11,C27*0.75,C27)),IF(I27="PROFESSOR DE ENSINO SUPERIOR EAD",IF(C27=40,4,2),0)) -> 4 | E27: =IF(OR(I27="PROFESSOR REGENTE",I27="PROFESSOR DE ENSINO SUPERIOR PRESENCIAL"),C27-D27,IF(C27=40,12,6)) -> 12 | F27: JULIANA MORAES DA SILVA | G27: 60216115949 | H27: ATIVO | I27: PROFESSOR DE ENSINO SUPERIOR EAD | U27: 24 | V27: Planejamento | W27: Unidade Acadêmica Com Base Regulatória | X27: Coordenador de Curso, Professor EAD, Professor Regente, Professor Mediador | Y27: Participação em Núcleo | Z27: UA com Base Regulatória | AA27: Atuar como membro de núcleos institucionais, contribuindo com análises, pareceres e propostas voltadas ao desenvolvimento pedagógico e à avaliação institucional, conforme as diretrizes da IES e legislação vigente. | AB27: Horas não letivas | AC27: Avaliar a periodicidade dessas atividades | AD27: Participação_Núcleo | AE27: 0 | AF27: 0.25 | AG27: =AF27+0.25 -> 0.5 | AH27: 0.75 | AI27: 1
A28: CLAUDIA CRISTINA BATISTELA FRANCISCO | B28: 012009003473 | C28: 40 | D28: =IF(I28="PROFESSOR REGENTE",IF(C28=40,C28*0.5,IF(C28>11,C28*0.75,C28)),IF(I28="PROFESSOR DE ENSINO SUPERIOR EAD",IF(C28=40,4,2),0)) -> 4 | E28: =IF(OR(I28="PROFESSOR REGENTE",I28="PROFESSOR DE ENSINO SUPERIOR PRESENCIAL"),C28-D28,IF(C28=40,12,6)) -> 12 | F28: JULIANA MORAES DA SILVA | G28: 03283083908 | H28: ATIVO | I28: PROFESSOR DE ENSINO SUPERIOR EAD | U28: 25 | V28: Ensino | W28: Orientação | X28: Professor EAD, Professor Regente | Y28: Disciplina EAD - Curso Presencial (Disciplinas On-line e Disciplinas Digitais) | Z28: Orient. Ensino - Demais | AA28: Cadastrar banco de questões. Realizar orientações aos estudantes, atendimento de protocolo e revisão de avaliação. | AB28: Horas não letivas | AC28: Deve ser feito registro por disciplina | AD28: Disciplinas_Digitais | AE28: 0 | AF28: 1 | AG28: =AF28+0.25 -> 1.25 | AH28: 1.5 | AI28: 1.75 | AJ28: 2
A29: CLEBER MENA LEAO JUNIOR | B29: 012009006141 | C29: 20 | D29: =IF(I29="PROFESSOR REGENTE",IF(C29=40,C29*0.5,IF(C29>11,C29*0.75,C29)),IF(I29="PROFESSOR DE ENSINO SUPERIOR EAD",IF(C29=40,4,2),0)) -> 2 | E29: =IF(OR(I29="PROFESSOR REGENTE",I29="PROFESSOR DE ENSINO SUPERIOR PRESENCIAL"),C29-D29,IF(C29=40,12,6)) -> 6 | F29: JULIANA MORAES DA SILVA | G29: 00517327007 | H29: ATIVO | I29: PROFESSOR DE ENSINO SUPERIOR EAD
A30: CRISTINA CEREZUELA | B30: 012009006182 | C30: 12 | D30: =IF(I30="PROFESSOR REGENTE",IF(C30=40,C30*0.5,IF(C30>11,C30*0.75,C30)),IF(I30="PROFESSOR DE ENSINO SUPERIOR EAD",IF(C30=40,4,2),0)) -> 9 | E30: =IF(OR(I30="PROFESSOR REGENTE",I30="PROFESSOR DE ENSINO SUPERIOR PRESENCIAL"),C30-D30,IF(C30=40,12,6)) -> 3 | F30: JULIANA MORAES DA SILVA | G30: 88380270991 | H30: ADMISSÃO PROX.MÊS | I30: PROFESSOR REGENTE
A31: CRISTINA KOZAN DE BRITO | B31: 012009006183 | C31: 12 | D31: =IF(I31="PROFESSOR REGENTE",IF(C31=40,C31*0.5,IF(C31>11,C31*0.75,C31)),IF(I31="PROFESSOR DE ENSINO SUPERIOR EAD",IF(C31=40,4,2),0)) -> 9 | E31: =IF(OR(I31="PROFESSOR REGENTE",I31="PROFESSOR DE ENSINO SUPERIOR PRESENCIAL"),C31-D31,IF(C31=40,12,6)) -> 3 | F31: JULIANA MORAES DA SILVA | G31: 04243159980 | H31: ADMISSÃO PROX.MÊS | I31: PROFESSOR REGENTE
A32: CYNTIA DANIELLE PINTO GOMES | B32: 012009006090 | C32: 20 | D32: =IF(I32="PROFESSOR REGENTE",IF(C32=40,C32*0.5,IF(C32>11,C32*0.75,C32)),IF(I32="PROFESSOR DE ENSINO SUPERIOR EAD",IF(C32=40,4,2),0)) -> 2 | E32: =IF(OR(I32="PROFESSOR REGENTE",I32="PROFESSOR DE ENSINO SUPERIOR PRESENCIAL"),C32-D32,IF(C32=40,12,6)) -> 6 | F32: JULIANA MORAES DA SILVA | G32: 03316790942 | H32: ATIVO | I32: PROFESSOR DE ENSINO SUPERIOR EAD
A33: DANIELA CARLA MONTEIRO | B33: 012009003455 | C33: 40 | D33: =IF(I33="PROFESSOR REGENTE",IF(C33=40,C33*0.5,IF(C33>11,C33*0.75,C33)),IF(I33="PROFESSOR DE ENSINO SUPERIOR EAD",IF(C33=40,4,2),0)) -> 4 | E33: =IF(OR(I33="PROFESSOR REGENTE",I33="PROFESSOR DE ENSINO SUPERIOR PRESENCIAL"),C33-D33,IF(C33=40,12,6)) -> 12 | F33: JULIANA MORAES DA SILVA | G33: 01922159905 | H33: ATIVO | I33: PROFESSOR DE ENSINO SUPERIOR EAD
A34: DANIELA FAGUNDES CARNELOS NUNES | B34: 012009006206 | C34: 12 | D34: =IF(I34="PROFESSOR REGENTE",IF(C34=40,C34*0.5,IF(C34>11,C34*0.75,C34)),IF(I34="PROFESSOR DE ENSINO SUPERIOR EAD",IF(C34=40,4,2),0)) -> 9 | E34: =IF(OR(I34="PROFESSOR REGENTE",I34="PROFESSOR DE ENSINO SUPERIOR PRESENCIAL"),C34-D34,IF(C34=40,12,6)) -> 3 | F34: JULIANA MORAES DA SILVA | G34: 07641785980 | H34: ADMISSÃO PROX.MÊS | I34: PROFESSOR REGENTE
A35: DANIELA SIKORSKI | B35: 012009003544 | C35: 20 | D35: =IF(I35="PROFESSOR REGENTE",IF(C35=40,C35*0.5,IF(C35>11,C35*0.75,C35)),IF(I35="PROFESSOR DE ENSINO SUPERIOR EAD",IF(C35=40,4,2),0)) -> 2 | E35: =IF(OR(I35="PROFESSOR REGENTE",I35="PROFESSOR DE ENSINO SUPERIOR PRESENCIAL"),C35-D35,IF(C35=40,12,6)) -> 6 | F35: JULIANA MORAES DA SILVA | G35: 02913298966 | H35: ATIVO | I35: PROFESSOR DE ENSINO SUPERIOR EAD
A36: DIOGO BOCHNIA ZULIANI | B36: 012009003457 | C36: 20 | D36: =IF(I36="PROFESSOR REGENTE",IF(C36=40,C36*0.5,IF(C36>11,C36*0.75,C36)),IF(I36="PROFESSOR DE ENSINO SUPERIOR EAD",IF(C36=40,4,2),0)) -> 2 | E36: =IF(OR(I36="PROFESSOR REGENTE",I36="PROFESSOR DE ENSINO SUPERIOR PRESENCIAL"),C36-D36,IF(C36=40,12,6)) -> 6 | F36: JULIANA MORAES DA SILVA | G36: 03872419900 | H36: ATIVO | I36: PROFESSOR DE ENSINO SUPERIOR EAD
A37: EDMILSON DE LIMA LESSA | B37: 012009005549 | C37: 20 | D37: =IF(I37="PROFESSOR REGENTE",IF(C37=40,C37*0.5,IF(C37>11,C37*0.75,C37)),IF(I37="PROFESSOR DE ENSINO SUPERIOR EAD",IF(C37=40,4,2),0)) -> 2 | E37: =IF(OR(I37="PROFESSOR REGENTE",I37="PROFESSOR DE ENSINO SUPERIOR PRESENCIAL"),C37-D37,IF(C37=40,12,6)) -> 6 | F37: GISLAINE CARDOSO DE SOUZA FIAES | G37: 08384214743 | H37: ATIVO | I37: PROFESSOR DE ENSINO SUPERIOR EAD
A38: EDSON RIBEIRO DE BRITTO DE ALMEIDA JUNIOR | B38: 012009005037 | C38: 40 | D38: =IF(I38="PROFESSOR REGENTE",IF(C38=40,C38*0.5,IF(C38>11,C38*0.75,C38)),IF(I38="PROFESSOR DE ENSINO SUPERIOR EAD",IF(C38=40,4,2),0)) -> 4 | E38: =IF(OR(I38="PROFESSOR REGENTE",I38="PROFESSOR DE ENSINO SUPERIOR PRESENCIAL"),C38-D38,IF(C38=40,12,6)) -> 12 | F38: JULIANA MORAES DA SILVA | G38: 09307081999 | H38: ATIVO | I38: PROFESSOR DE ENSINO SUPERIOR EAD
A39: EDUARDO SALES DE LIMA | B39: 012009003704 | C39: 20 | D39: =IF(I39="PROFESSOR REGENTE",IF(C39=40,C39*0.5,IF(C39>11,C39*0.75,C39)),IF(I39="PROFESSOR DE ENSINO SUPERIOR EAD",IF(C39=40,4,2),0)) -> 2 | E39: =IF(OR(I39="PROFESSOR REGENTE",I39="PROFESSOR DE ENSINO SUPERIOR PRESENCIAL"),C39-D39,IF(C39=40,12,6)) -> 6 | F39: JULIANA MORAES DA SILVA | G39: 26631459800 | H39: ATIVO | I39: PROFESSOR DE ENSINO SUPERIOR EAD
A40: ELIEL NERIS JOAQUIM | B40: 012009006198 | C40: 12 | D40: =IF(I40="PROFESSOR REGENTE",IF(C40=40,C40*0.5,IF(C40>11,C40*0.75,C40)),IF(I40="PROFESSOR DE ENSINO SUPERIOR EAD",IF(C40=40,4,2),0)) -> 9 | E40: =IF(OR(I40="PROFESSOR REGENTE",I40="PROFESSOR DE ENSINO SUPERIOR PRESENCIAL"),C40-D40,IF(C40=40,12,6)) -> 3 | F40: JULIANA MORAES DA SILVA | G40: 04759793976 | H40: ADMISSÃO PROX.MÊS | I40: PROFESSOR REGENTE
...

Sheet PREENCHIMENTO|LETIVAS
A1: Devem ser inseridas: - Disciplinas com aulas transmitidas ao vivo; - Disciplinas com aulas que tenham sido gravadas especificamente para serem usadas ao vivo neste módulo; Não devem ser inseridas: - Disciplinas com aulas reaproveitadas de anos anteriores; - Disciplinas sem aulas ao vivo;
A8: LISTAS SUSPENSAS (Apenas Seleção) | J8: DIGITÁVEIS
A9: PROFESSOR(A) | B9: CHAPA | C9: CH SEMANAL | D9: CH LETIVA | E9: CARGO | F9: MÓDULO | G9: ORDEM | H9: DIA DA TRANSMISSÃO | I9: HORÁRIO | J9: DISCIPLINA (NOME) | K9: OBSERVAÇÃO | L9: R$ (RPA)
A10: AMANDA FERREIRA GUIMARAES | B10: =IF(_xlfn.XLOOKUP(A10,PARAMETROS!A:A,PARAMETROS!B:B)=0,"",_xlfn.XLOOKUP(A10,PARAMETROS!A:A,PARAMETROS!B:B)) -> 012009006176 | C10: =IF(_xlfn.XLOOKUP(A10,PARAMETROS!A:A,PARAMETROS!C:C)=0,"",_xlfn.XLOOKUP(A10,PARAMETROS!A:A,PARAMETROS!C:C)) -> 12 | D10: =IF(_xlfn.XLOOKUP(A10,PARAMETROS!A:A,PARAMETROS!D:D)=0,"",_xlfn.XLOOKUP(A10,PARAMETROS!A:A,PARAMETROS!D:D)) -> 9 | E10: =IF(_xlfn.XLOOKUP('PREENCHIMENTO|LETIVAS'!A10,PARAMETROS!A:A,PARAMETROS!I:I)=0,"",_xlfn.XLOOKUP('PREENCHIMENTO|LETIVAS'!A10,PARAMETROS!A:A,PARAMETROS!I:I)) -> PROFESSOR REGENTE | F10: 51|2026 | G10: 1 | H10: 4 - Quarta | I10: 20:40 às 22:10 | J10: GESTÃO DE PESSOAS E DESENVOLVIMENTO DE EQUIPES | W10: =IF(I10<>"",2,0) -> 2
A11: IZABELLA DURANTE TEMPORINI FURTADO | B11: =IF(_xlfn.XLOOKUP(A11,PARAMETROS!A:A,PARAMETROS!B:B)=0,"",_xlfn.XLOOKUP(A11,PARAMETROS!A:A,PARAMETROS!B:B)) -> 012009006192 | C11: =IF(_xlfn.XLOOKUP(A11,PARAMETROS!A:A,PARAMETROS!C:C)=0,"",_xlfn.XLOOKUP(A11,PARAMETROS!A:A,PARAMETROS!C:C)) -> 12 | D11: =IF(_xlfn.XLOOKUP(A11,PARAMETROS!A:A,PARAMETROS!D:D)=0,"",_xlfn.XLOOKUP(A11,PARAMETROS!A:A,PARAMETROS!D:D)) -> 9 | E11: =IF(_xlfn.XLOOKUP('PREENCHIMENTO|LETIVAS'!A11,PARAMETROS!A:A,PARAMETROS!I:I)=0,"",_xlfn.XLOOKUP('PREENCHIMENTO|LETIVAS'!A11,PARAMETROS!A:A,PARAMETROS!I:I)) -> PROFESSOR REGENTE | F11: 51|2026 | G11: 2 | H11: 4 - Quarta | I11: 19:00 às 20:30 | J11: ESTATÍSTICA | W11: =IF(I11<>"",2,0) -> 2
A12: IZABELLA DURANTE TEMPORINI FURTADO | B12: =IF(_xlfn.XLOOKUP(A12,PARAMETROS!A:A,PARAMETROS!B:B)=0,"",_xlfn.XLOOKUP(A12,PARAMETROS!A:A,PARAMETROS!B:B)) -> 012009006192 | C12: =IF(_xlfn.XLOOKUP(A12,PARAMETROS!A:A,PARAMETROS!C:C)=0,"",_xlfn.XLOOKUP(A12,PARAMETROS!A:A,PARAMETROS!C:C)) -> 12 | D12: =IF(_xlfn.XLOOKUP(A12,PARAMETROS!A:A,PARAMETROS!D:D)=0,"",_xlfn.XLOOKUP(A12,PARAMETROS!A:A,PARAMETROS!D:D)) -> 9 | E12: =IF(_xlfn.XLOOKUP('PREENCHIMENTO|LETIVAS'!A12,PARAMETROS!A:A,PARAMETROS!I:I)=0,"",_xlfn.XLOOKUP('PREENCHIMENTO|LETIVAS'!A12,PARAMETROS!A:A,PARAMETROS!I:I)) -> PROFESSOR REGENTE | F12: 51|2026 | G12: 1 | H12: 5 - Quinta | I12: 19:00 às 20:30 | J12: GEOMETRIA ANALÍTICA E ÁLGEBRA LINEAR | W12: =IF(I12<>"",2,0) -> 2
A13: IZABELLA DURANTE TEMPORINI FURTADO | B13: =IF(_xlfn.XLOOKUP(A13,PARAMETROS!A:A,PARAMETROS!B:B)=0,"",_xlfn.XLOOKUP(A13,PARAMETROS!A:A,PARAMETROS!B:B)) -> 012009006192 | C13: =IF(_xlfn.XLOOKUP(A13,PARAMETROS!A:A,PARAMETROS!C:C)=0,"",_xlfn.XLOOKUP(A13,PARAMETROS!A:A,PARAMETROS!C:C)) -> 12 | D13: =IF(_xlfn.XLOOKUP(A13,PARAMETROS!A:A,PARAMETROS!D:D)=0,"",_xlfn.XLOOKUP(A13,PARAMETROS!A:A,PARAMETROS!D:D)) -> 9 | E13: =IF(_xlfn.XLOOKUP('PREENCHIMENTO|LETIVAS'!A13,PARAMETROS!A:A,PARAMETROS!I:I)=0,"",_xlfn.XLOOKUP('PREENCHIMENTO|LETIVAS'!A13,PARAMETROS!A:A,PARAMETROS!I:I)) -> PROFESSOR REGENTE | F13: 51|2026 | G13: 2 | H13: 4 - Quarta | I13: 20:40 às 22:10 | J13: PROBABILIDADE E ESTATÍSTICA PARA ANÁLISE DE DADOS | W13: =IF(I13<>"",2,0) -> 2
A14: IZABELLA DURANTE TEMPORINI FURTADO | B14: =IF(_xlfn.XLOOKUP(A14,PARAMETROS!A:A,PARAMETROS!B:B)=0,"",_xlfn.XLOOKUP(A14,PARAMETROS!A:A,PARAMETROS!B:B)) -> 012009006192 | C14: =IF(_xlfn.XLOOKUP(A14,PARAMETROS!A:A,PARAMETROS!C:C)=0,"",_xlfn.XLOOKUP(A14,PARAMETROS!A:A,PARAMETROS!C:C)) -> 12 | D14: =IF(_xlfn.XLOOKUP(A14,PARAMETROS!A:A,PARAMETROS!D:D)=0,"",_xlfn.XLOOKUP(A14,PARAMETROS!A:A,PARAMETROS!D:D)) -> 9 | E14: =IF(_xlfn.XLOOKUP('PREENCHIMENTO|LETIVAS'!A14,PARAMETROS!A:A,PARAMETROS!I:I)=0,"",_xlfn.XLOOKUP('PREENCHIMENTO|LETIVAS'!A14,PARAMETROS!A:A,PARAMETROS!I:I)) -> PROFESSOR REGENTE | F14: 51|2026 | G14: 2 | H14: 5 - Quinta | I14: 19:00 às 20:30 | J14: CÁLCULO APLICADO À QUÍMICA | W14: =IF(I14<>"",2,0) -> 2
A15: ADRIANO APARECIDO DE OLIVEIRA | B15: =IF(_xlfn.XLOOKUP(A15,PARAMETROS!A:A,PARAMETROS!B:B)=0,"",_xlfn.XLOOKUP(A15,PARAMETROS!A:A,PARAMETROS!B:B)) -> 012009003424 | C15: =IF(_xlfn.XLOOKUP(A15,PARAMETROS!A:A,PARAMETROS!C:C)=0,"",_xlfn.XLOOKUP(A15,PARAMETROS!A:A,PARAMETROS!C:C)) -> 40 | D15: =IF(_xlfn.XLOOKUP(A15,PARAMETROS!A:A,PARAMETROS!D:D)=0,"",_xlfn.XLOOKUP(A15,PARAMETROS!A:A,PARAMETROS!D:D)) -> 20 | E15: =IF(_xlfn.XLOOKUP('PREENCHIMENTO|LETIVAS'!A15,PARAMETROS!A:A,PARAMETROS!I:I)=0,"",_xlfn.XLOOKUP('PREENCHIMENTO|LETIVAS'!A15,PARAMETROS!A:A,PARAMETROS!I:I)) -> PROFESSOR REGENTE | F15: 51|2026 | G15: 1 | H15: 2 - Segunda | I15: 20:40 às 22:10 | J15: MENTALIDADE CRIATIVA E EMPREENDEDORA | W15: =IF(I15<>"",2,0) -> 2
A16: ADRIANO APARECIDO DE OLIVEIRA | B16: =IF(_xlfn.XLOOKUP(A16,PARAMETROS!A:A,PARAMETROS!B:B)=0,"",_xlfn.XLOOKUP(A16,PARAMETROS!A:A,PARAMETROS!B:B)) -> 012009003424 | C16: =IF(_xlfn.XLOOKUP(A16,PARAMETROS!A:A,PARAMETROS!C:C)=0,"",_xlfn.XLOOKUP(A16,PARAMETROS!A:A,PARAMETROS!C:C)) -> 40 | D16: =IF(_xlfn.XLOOKUP(A16,PARAMETROS!A:A,PARAMETROS!D:D)=0,"",_xlfn.XLOOKUP(A16,PARAMETROS!A:A,PARAMETROS!D:D)) -> 20 | E16: =IF(_xlfn.XLOOKUP('PREENCHIMENTO|LETIVAS'!A16,PARAMETROS!A:A,PARAMETROS!I:I)=0,"",_xlfn.XLOOKUP('PREENCHIMENTO|LETIVAS'!A16,PARAMETROS!A:A,PARAMETROS!I:I)) -> PROFESSOR REGENTE | F16: 51|2026 | G16: 1 | H16: 3 - Terça | I16: 20:40 às 22:10 | J16: MENTALIDADE CRIATIVA E EMPREENDEDORA | W16: =IF(I16<>"",2,0) -> 2
A17: ADRIANO APARECIDO DE OLIVEIRA | B17: =IF(_xlfn.XLOOKUP(A17,PARAMETROS!A:A,PARAMETROS!B:B)=0,"",_xlfn.XLOOKUP(A17,PARAMETROS!A:A,PARAMETROS!B:B)) -> 012009003424 | C17: =IF(_xlfn.XLOOKUP(A17,PARAMETROS!A:A,PARAMETROS!C:C)=0,"",_xlfn.XLOOKUP(A17,PARAMETROS!A:A,PARAMETROS!C:C)) -> 40 | D17: =IF(_xlfn.XLOOKUP(A17,PARAMETROS!A:A,PARAMETROS!D:D)=0,"",_xlfn.XLOOKUP(A17,PARAMETROS!A:A,PARAMETROS!D:D)) -> 20 | E17: =IF(_xlfn.XLOOKUP('PREENCHIMENTO|LETIVAS'!A17,PARAMETROS!A:A,PARAMETROS!I:I)=0,"",_xlfn.XLOOKUP('PREENCHIMENTO|LETIVAS'!A17,PARAMETROS!A:A,PARAMETROS!I:I)) -> PROFESSOR REGENTE | F17: 51|2026 | G17: 1 | H17: 4 - Quarta | I17: 20:40 às 22:10 | J17: MENTALIDADE CRIATIVA E EMPREENDEDORA | W17: =IF(I17<>"",2,0) -> 2
A18: ADRIANO APARECIDO DE OLIVEIRA | B18: =IF(_xlfn.XLOOKUP(A18,PARAMETROS!A:A,PARAMETROS!B:B)=0,"",_xlfn.XLOOKUP(A18,PARAMETROS!A:A,PARAMETROS!B:B)) -> 012009003424 | C18: =IF(_xlfn.XLOOKUP(A18,PARAMETROS!A:A,PARAMETROS!C:C)=0,"",_xlfn.XLOOKUP(A18,PARAMETROS!A:A,PARAMETROS!C:C)) -> 40 | D18: =IF(_xlfn.XLOOKUP(A18,PARAMETROS!A:A,PARAMETROS!D:D)=0,"",_xlfn.XLOOKUP(A18,PARAMETROS!A:A,PARAMETROS!D:D)) -> 20 | E18: =IF(_xlfn.XLOOKUP('PREENCHIMENTO|LETIVAS'!A18,PARAMETROS!A:A,PARAMETROS!I:I)=0,"",_xlfn.XLOOKUP('PREENCHIMENTO|LETIVAS'!A18,PARAMETROS!A:A,PARAMETROS!I:I)) -> PROFESSOR REGENTE | F18: 51|2026 | G18: 1 | H18: 5 - Quinta | I18: 20:40 às 22:10 | J18: MENTALIDADE CRIATIVA E EMPREENDEDORA | W18: =IF(I18<>"",2,0) -> 2
A19: LUIS FERNANDO MOREIRA DA SILVA | B19: =IF(_xlfn.XLOOKUP(A19,PARAMETROS!A:A,PARAMETROS!B:B)=0,"",_xlfn.XLOOKUP(A19,PARAMETROS!A:A,PARAMETROS!B:B)) -> 012009006245 | C19: =IF(_xlfn.XLOOKUP(A19,PARAMETROS!A:A,PARAMETROS!C:C)=0,"",_xlfn.XLOOKUP(A19,PARAMETROS!A:A,PARAMETROS!C:C)) -> 12 | D19: =IF(_xlfn.XLOOKUP(A19,PARAMETROS!A:A,PARAMETROS!D:D)=0,"",_xlfn.XLOOKUP(A19,PARAMETROS!A:A,PARAMETROS!D:D)) -> 9 | E19: =IF(_xlfn.XLOOKUP('PREENCHIMENTO|LETIVAS'!A19,PARAMETROS!A:A,PARAMETROS!I:I)=0,"",_xlfn.XLOOKUP('PREENCHIMENTO|LETIVAS'!A19,PARAMETROS!A:A,PARAMETROS!I:I)) -> PROFESSOR REGENTE | F19: 51|2026 | G19: ESTENDIDA | H19: 2 - Segunda | I19: 20:40 às 22:10 | J19: CONCEITOS DA ADMINISTRAÇÃO E ÉTICA EMPRESARIAL | W19: =IF(I19<>"",2,0) -> 2
A20: LUIS FERNANDO MOREIRA DA SILVA | B20: =IF(_xlfn.XLOOKUP(A20,PARAMETROS!A:A,PARAMETROS!B:B)=0,"",_xlfn.XLOOKUP(A20,PARAMETROS!A:A,PARAMETROS!B:B)) -> 012009006245 | C20: =IF(_xlfn.XLOOKUP(A20,PARAMETROS!A:A,PARAMETROS!C:C)=0,"",_xlfn.XLOOKUP(A20,PARAMETROS!A:A,PARAMETROS!C:C)) -> 12 | D20: =IF(_xlfn.XLOOKUP(A20,PARAMETROS!A:A,PARAMETROS!D:D)=0,"",_xlfn.XLOOKUP(A20,PARAMETROS!A:A,PARAMETROS!D:D)) -> 9 | E20: =IF(_xlfn.XLOOKUP('PREENCHIMENTO|LETIVAS'!A20,PARAMETROS!A:A,PARAMETROS!I:I)=0,"",_xlfn.XLOOKUP('PREENCHIMENTO|LETIVAS'!A20,PARAMETROS!A:A,PARAMETROS!I:I)) -> PROFESSOR REGENTE | F20: 51|2026 | G20: 1 | H20: 2 - Segunda | I20: 19:00 às 20:30 | J20: TEORIAS DA ADMINISTRAÇÃO | W20: =IF(I20<>"",2,0) -> 2
A21: LUIS FERNANDO MOREIRA DA SILVA | B21: =IF(_xlfn.XLOOKUP(A21,PARAMETROS!A:A,PARAMETROS!B:B)=0,"",_xlfn.XLOOKUP(A21,PARAMETROS!A:A,PARAMETROS!B:B)) -> 012009006245 | C21: =IF(_xlfn.XLOOKUP(A21,PARAMETROS!A:A,PARAMETROS!C:C)=0,"",_xlfn.XLOOKUP(A21,PARAMETROS!A:A,PARAMETROS!C:C)) -> 12 | D21: =IF(_xlfn.XLOOKUP(A21,PARAMETROS!A:A,PARAMETROS!D:D)=0,"",_xlfn.XLOOKUP(A21,PARAMETROS!A:A,PARAMETROS!D:D)) -> 9 | E21: =IF(_xlfn.XLOOKUP('PREENCHIMENTO|LETIVAS'!A21,PARAMETROS!A:A,PARAMETROS!I:I)=0,"",_xlfn.XLOOKUP('PREENCHIMENTO|LETIVAS'!A21,PARAMETROS!A:A,PARAMETROS!I:I)) -> PROFESSOR REGENTE | F21: 51|2026 | G21: 2 | H21: 3 - Terça | I21: 19:00 às 20:30 | J21: PESQUISA DE OPINIÃO PÚBLICA | W21: =IF(I21<>"",2,0) -> 2
A22: ELAINE SANTOS | B22: =IF(_xlfn.XLOOKUP(A22,PARAMETROS!A:A,PARAMETROS!B:B)=0,"",_xlfn.XLOOKUP(A22,PARAMETROS!A:A,PARAMETROS!B:B)) -> 012009006265 | C22: =IF(_xlfn.XLOOKUP(A22,PARAMETROS!A:A,PARAMETROS!C:C)=0,"",_xlfn.XLOOKUP(A22,PARAMETROS!A:A,PARAMETROS!C:C)) -> 12 | D22: =IF(_xlfn.XLOOKUP(A22,PARAMETROS!A:A,PARAMETROS!D:D)=0,"",_xlfn.XLOOKUP(A22,PARAMETROS!A:A,PARAMETROS!D:D)) -> 9 | E22: =IF(_xlfn.XLOOKUP('PREENCHIMENTO|LETIVAS'!A22,PARAMETROS!A:A,PARAMETROS!I:I)=0,"",_xlfn.XLOOKUP('PREENCHIMENTO|LETIVAS'!A22,PARAMETROS!A:A,PARAMETROS!I:I)) -> PROFESSOR REGENTE | F22: 51|2026 | G22: ESTENDIDA | H22: 2 - Segunda | I22: 20:40 às 22:10 | J22: PROGRAMAÇÃO E CÁLCULO NUMÉRICO | W22: =IF(I22<>"",2,0) -> 2
A23: ELAINE SANTOS | B23: =IF(_xlfn.XLOOKUP(A23,PARAMETROS!A:A,PARAMETROS!B:B)=0,"",_xlfn.XLOOKUP(A23,PARAMETROS!A:A,PARAMETROS!B:B)) -> 012009006265 | C23: =IF(_xlfn.XLOOKUP(A23,PARAMETROS!A:A,PARAMETROS!C:C)=0,"",_xlfn.XLOOKUP(A23,PARAMETROS!A:A,PARAMETROS!C:C)) -> 12 | D23: =IF(_xlfn.XLOOKUP(A23,PARAMETROS!A:A,PARAMETROS!D:D)=0,"",_xlfn.XLOOKUP(A23,PARAMETROS!A:A,PARAMETROS!D:D)) -> 9 | E23: =IF(_xlfn.XLOOKUP('PREENCHIMENTO|LETIVAS'!A23,PARAMETROS!A:A,PARAMETROS!I:I)=0,"",_xlfn.XLOOKUP('PREENCHIMENTO|LETIVAS'!A23,PARAMETROS!A:A,PARAMETROS!I:I)) -> PROFESSOR REGENTE | F23: 51|2026 | G23: ESTENDIDA | H23: 2 - Segunda | I23: 19:00 às 20:30 | J23: SISTEMAS DE ENERGIA SOLAR TÉRMICA E FOTOVOLTAICA | W23: =IF(I23<>"",2,0) -> 2
A24: GUSTAVO GONCALVES KREPSKI | B24: =IF(_xlfn.XLOOKUP(A24,PARAMETROS!A:A,PARAMETROS!B:B)=0,"",_xlfn.XLOOKUP(A24,PARAMETROS!A:A,PARAMETROS!B:B)) -> 012009004339 | C24: =IF(_xlfn.XLOOKUP(A24,PARAMETROS!A:A,PARAMETROS!C:C)=0,"",_xlfn.XLOOKUP(A24,PARAMETROS!A:A,PARAMETROS!C:C)) -> 40 | D24: =IF(_xlfn.XLOOKUP(A24,PARAMETROS!A:A,PARAMETROS!D:D)=0,"",_xlfn.XLOOKUP(A24,PARAMETROS!A:A,PARAMETROS!D:D)) -> 20 | E24: =IF(_xlfn.XLOOKUP('PREENCHIMENTO|LETIVAS'!A24,PARAMETROS!A:A,PARAMETROS!I:I)=0,"",_xlfn.XLOOKUP('PREENCHIMENTO|LETIVAS'!A24,PARAMETROS!A:A,PARAMETROS!I:I)) -> PROFESSOR REGENTE | F24: 51|2026 | G24: ESTENDIDA | H24: 2 - Segunda | I24: 19:00 às 20:30 | J24: ELETRÔNICA ANALÓGICA | W24: =IF(I24<>"",2,0) -> 2
A25: GUSTAVO GONCALVES KREPSKI | B25: =IF(_xlfn.XLOOKUP(A25,PARAMETROS!A:A,PARAMETROS!B:B)=0,"",_xlfn.XLOOKUP(A25,PARAMETROS!A:A,PARAMETROS!B:B)) -> 012009004339 | C25: =IF(_xlfn.XLOOKUP(A25,PARAMETROS!A:A,PARAMETROS!C:C)=0,"",_xlfn.XLOOKUP(A25,PARAMETROS!A:A,PARAMETROS!C:C)) -> 40 | D25: =IF(_xlfn.XLOOKUP(A25,PARAMETROS!A:A,PARAMETROS!D:D)=0,"",_xlfn.XLOOKUP(A25,PARAMETROS!A:A,PARAMETROS!D:D)) -> 20 | E25: =IF(_xlfn.XLOOKUP('PREENCHIMENTO|LETIVAS'!A25,PARAMETROS!A:A,PARAMETROS!I:I)=0,"",_xlfn.XLOOKUP('PREENCHIMENTO|LETIVAS'!A25,PARAMETROS!A:A,PARAMETROS!I:I)) -> PROFESSOR REGENTE | F25: 51|2026 | G25: ESTENDIDA | H25: 2 - Segunda | I25: 20:40 às 22:10 | J25: SINAIS E SISTEMAS LINEARES | W25: =IF(I25<>"",2,0) -> 2
A26: UGO ANDREATA GALIMBERTTI | B26: =IF(_xlfn.XLOOKUP(A26,PARAMETROS!A:A,PARAMETROS!B:B)=0,"",_xlfn.XLOOKUP(A26,PARAMETROS!A:A,PARAMETROS!B:B)) -> 012009006226 | C26: =IF(_xlfn.XLOOKUP(A26,PARAMETROS!A:A,PARAMETROS!C:C)=0,"",_xlfn.XLOOKUP(A26,PARAMETROS!A:A,PARAMETROS!C:C)) -> 40 | D26: =IF(_xlfn.XLOOKUP(A26,PARAMETROS!A:A,PARAMETROS!D:D)=0,"",_xlfn.XLOOKUP(A26,PARAMETROS!A:A,PARAMETROS!D:D)) -> 20 | E26: =IF(_xlfn.XLOOKUP('PREENCHIMENTO|LETIVAS'!A26,PARAMETROS!A:A,PARAMETROS!I:I)=0,"",_xlfn.XLOOKUP('PREENCHIMENTO|LETIVAS'!A26,PARAMETROS!A:A,PARAMETROS!I:I)) -> PROFESSOR REGENTE | F26: 51|2026 | G26: ESTENDIDA | H26: 3 - Terça | I26: 19:00 às 20:30 | J26: ATELIÊ DE ARQUITETURA: EDIFÍCIOS VERTICAIS | W26: =IF(I26<>"",2,0) -> 2
A27: UGO ANDREATA GALIMBERTTI | B27: =IF(_xlfn.XLOOKUP(A27,PARAMETROS!A:A,PARAMETROS!B:B)=0,"",_xlfn.XLOOKUP(A27,PARAMETROS!A:A,PARAMETROS!B:B)) -> 012009006226 | C27: =IF(_xlfn.XLOOKUP(A27,PARAMETROS!A:A,PARAMETROS!C:C)=0,"",_xlfn.XLOOKUP(A27,PARAMETROS!A:A,PARAMETROS!C:C)) -> 40 | D27: =IF(_xlfn.XLOOKUP(A27,PARAMETROS!A:A,PARAMETROS!D:D)=0,"",_xlfn.XLOOKUP(A27,PARAMETROS!A:A,PARAMETROS!D:D)) -> 20 | E27: =IF(_xlfn.XLOOKUP('PREENCHIMENTO|LETIVAS'!A27,PARAMETROS!A:A,PARAMETROS!I:I)=0,"",_xlfn.XLOOKUP('PREENCHIMENTO|LETIVAS'!A27,PARAMETROS!A:A,PARAMETROS!I:I)) -> PROFESSOR REGENTE | F27: 51|2026 | G27: ESTENDIDA | H27: 3 - Terça | I27: 19:00 às 20:30 | J27: ATELIÊ DE PROJETO DE ARQUITETURA: EDIFÍCIOS VERTICAIS | W27: =IF(I27<>"",2,0) -> 2
A28: UGO ANDREATA GALIMBERTTI | B28: =IF(_xlfn.XLOOKUP(A28,PARAMETROS!A:A,PARAMETROS!B:B)=0,"",_xlfn.XLOOKUP(A28,PARAMETROS!A:A,PARAMETROS!B:B)) -> 012009006226 | C28: =IF(_xlfn.XLOOKUP(A28,PARAMETROS!A:A,PARAMETROS!C:C)=0,"",_xlfn.XLOOKUP(A28,PARAMETROS!A:A,PARAMETROS!C:C)) -> 40 | D28: =IF(_xlfn.XLOOKUP(A28,PARAMETROS!A:A,PARAMETROS!D:D)=0,"",_xlfn.XLOOKUP(A28,PARAMETROS!A:A,PARAMETROS!D:D)) -> 20 | E28: =IF(_xlfn.XLOOKUP('PREENCHIMENTO|LETIVAS'!A28,PARAMETROS!A:A,PARAMETROS!I:I)=0,"",_xlfn.XLOOKUP('PREENCHIMENTO|LETIVAS'!A28,PARAMETROS!A:A,PARAMETROS!I:I)) -> PROFESSOR REGENTE | F28: 51|2026 | G28: ESTENDIDA | H28: 4 - Quarta | I28: 19:00 às 20:30 | J28: DESENHO ARQUITETÔNICO AUXILIADO POR COMPUTADOR | W28: =IF(I28<>"",2,0) -> 2
A29: UGO ANDREATA GALIMBERTTI | B29: =IF(_xlfn.XLOOKUP(A29,PARAMETROS!A:A,PARAMETROS!B:B)=0,"",_xlfn.XLOOKUP(A29,PARAMETROS!A:A,PARAMETROS!B:B)) -> 012009006226 | C29: =IF(_xlfn.XLOOKUP(A29,PARAMETROS!A:A,PARAMETROS!C:C)=0,"",_xlfn.XLOOKUP(A29,PARAMETROS!A:A,PARAMETROS!C:C)) -> 40 | D29: =IF(_xlfn.XLOOKUP(A29,PARAMETROS!A:A,PARAMETROS!D:D)=0,"",_xlfn.XLOOKUP(A29,PARAMETROS!A:A,PARAMETROS!D:D)) -> 20 | E29: =IF(_xlfn.XLOOKUP('PREENCHIMENTO|LETIVAS'!A29,PARAMETROS!A:A,PARAMETROS!I:I)=0,"",_xlfn.XLOOKUP('PREENCHIMENTO|LETIVAS'!A29,PARAMETROS!A:A,PARAMETROS!I:I)) -> PROFESSOR REGENTE | F29: 51|2026 | G29: ESTENDIDA | H29: 4 - Quarta | I29: 20:40 às 22:10 | J29: DESENHO UNIVERSAL | W29: =IF(I29<>"",2,0) -> 2
A30: UGO ANDREATA GALIMBERTTI | B30: =IF(_xlfn.XLOOKUP(A30,PARAMETROS!A:A,PARAMETROS!B:B)=0,"",_xlfn.XLOOKUP(A30,PARAMETROS!A:A,PARAMETROS!B:B)) -> 012009006226 | C30: =IF(_xlfn.XLOOKUP(A30,PARAMETROS!A:A,PARAMETROS!C:C)=0,"",_xlfn.XLOOKUP(A30,PARAMETROS!A:A,PARAMETROS!C:C)) -> 40 | D30: =IF(_xlfn.XLOOKUP(A30,PARAMETROS!A:A,PARAMETROS!D:D)=0,"",_xlfn.XLOOKUP(A30,PARAMETROS!A:A,PARAMETROS!D:D)) -> 20 | E30: =IF(_xlfn.XLOOKUP('PREENCHIMENTO|LETIVAS'!A30,PARAMETROS!A:A,PARAMETROS!I:I)=0,"",_xlfn.XLOOKUP('PREENCHIMENTO|LETIVAS'!A30,PARAMETROS!A:A,PARAMETROS!I:I)) -> PROFESSOR REGENTE | F30: 51|2026 | G30: ESTENDIDA | H30: 2 - Segunda | I30: 19:00 às 20:30 | J30: DESENHO TÉCNICO | W30: =IF(I30<>"",2,0) -> 2
A31: BRUNA EDUARDA KUBLISKI FOLMER ROMAN | B31: =IF(_xlfn.XLOOKUP(A31,PARAMETROS!A:A,PARAMETROS!B:B)=0,"",_xlfn.XLOOKUP(A31,PARAMETROS!A:A,PARAMETROS!B:B)) -> 012009006311 | C31: =IF(_xlfn.XLOOKUP(A31,PARAMETROS!A:A,PARAMETROS!C:C)=0,"",_xlfn.XLOOKUP(A31,PARAMETROS!A:A,PARAMETROS!C:C)) -> 12 | D31: =IF(_xlfn.XLOOKUP(A31,PARAMETROS!A:A,PARAMETROS!D:D)=0,"",_xlfn.XLOOKUP(A31,PARAMETROS!A:A,PARAMETROS!D:D)) -> 9 | E31: =IF(_xlfn.XLOOKUP('PREENCHIMENTO|LETIVAS'!A31,PARAMETROS!A:A,PARAMETROS!I:I)=0,"",_xlfn.XLOOKUP('PREENCHIMENTO|LETIVAS'!A31,PARAMETROS!A:A,PARAMETROS!I:I)) -> PROFESSOR REGENTE | F31: 51|2026 | G31: ESTENDIDA | H31: 4 - Quarta | I31: 19:00 às 20:30 | J31: ATELIÊ DE PROJETO DE ARQUITETURA: RESIDENCIAL | W31: =IF(I31<>"",2,0) -> 2
A32: BRUNA EDUARDA KUBLISKI FOLMER ROMAN | B32: =IF(_xlfn.XLOOKUP(A32,PARAMETROS!A:A,PARAMETROS!B:B)=0,"",_xlfn.XLOOKUP(A32,PARAMETROS!A:A,PARAMETROS!B:B)) -> 012009006311 | C32: =IF(_xlfn.XLOOKUP(A32,PARAMETROS!A:A,PARAMETROS!C:C)=0,"",_xlfn.XLOOKUP(A32,PARAMETROS!A:A,PARAMETROS!C:C)) -> 12 | D32: =IF(_xlfn.XLOOKUP(A32,PARAMETROS!A:A,PARAMETROS!D:D)=0,"",_xlfn.XLOOKUP(A32,PARAMETROS!A:A,PARAMETROS!D:D)) -> 9 | E32: =IF(_xlfn.XLOOKUP('PREENCHIMENTO|LETIVAS'!A32,PARAMETROS!A:A,PARAMETROS!I:I)=0,"",_xlfn.XLOOKUP('PREENCHIMENTO|LETIVAS'!A32,PARAMETROS!A:A,PARAMETROS!I:I)) -> PROFESSOR REGENTE | F32: 51|2026 | G32: ESTENDIDA | H32: 4 - Quarta | I32: 20:40 às 22:10 | J32: TEORIA DA ARQUITETURA E URBANISMO | W32: =IF(I32<>"",2,0) -> 2
A33: LUCAS MEN BENATTI | B33: =IF(_xlfn.XLOOKUP(A33,PARAMETROS!A:A,PARAMETROS!B:B)=0,"",_xlfn.XLOOKUP(A33,PARAMETROS!A:A,PARAMETROS!B:B)) -> 012009006258 | C33: =IF(_xlfn.XLOOKUP(A33,PARAMETROS!A:A,PARAMETROS!C:C)=0,"",_xlfn.XLOOKUP(A33,PARAMETROS!A:A,PARAMETROS!C:C)) -> 12 | D33: =IF(_xlfn.XLOOKUP(A33,PARAMETROS!A:A,PARAMETROS!D:D)=0,"",_xlfn.XLOOKUP(A33,PARAMETROS!A:A,PARAMETROS!D:D)) -> 9 | E33: =IF(_xlfn.XLOOKUP('PREENCHIMENTO|LETIVAS'!A33,PARAMETROS!A:A,PARAMETROS!I:I)=0,"",_xlfn.XLOOKUP('PREENCHIMENTO|LETIVAS'!A33,PARAMETROS!A:A,PARAMETROS!I:I)) -> PROFESSOR REGENTE | F33: 51|2026 | G33: ESTENDIDA | H33: 4 - Quarta | I33: 19:00 às 20:30 | J33: ESTÉTICA E HISTÓRIA DA ARTE | W33: =IF(I33<>"",2,0) -> 2
A34: LUCAS MEN BENATTI | B34: =IF(_xlfn.XLOOKUP(A34,PARAMETROS!A:A,PARAMETROS!B:B)=0,"",_xlfn.XLOOKUP(A34,PARAMETROS!A:A,PARAMETROS!B:B)) -> 012009006258 | C34: =IF(_xlfn.XLOOKUP(A34,PARAMETROS!A:A,PARAMETROS!C:C)=0,"",_xlfn.XLOOKUP(A34,PARAMETROS!A:A,PARAMETROS!C:C)) -> 12 | D34: =IF(_xlfn.XLOOKUP(A34,PARAMETROS!A:A,PARAMETROS!D:D)=0,"",_xlfn.XLOOKUP(A34,PARAMETROS!A:A,PARAMETROS!D:D)) -> 9 | E34: =IF(_xlfn.XLOOKUP('PREENCHIMENTO|LETIVAS'!A34,PARAMETROS!A:A,PARAMETROS!I:I)=0,"",_xlfn.XLOOKUP('PREENCHIMENTO|LETIVAS'!A34,PARAMETROS!A:A,PARAMETROS!I:I)) -> PROFESSOR REGENTE | F34: 51|2026 | G34: 2 | H34: 5 - Quinta | I34: 19:00 às 20:30 | J34: ARTE CONTEMPORÂNEA | W34: =IF(I34<>"",2,0) -> 2
A35: LEONARDO DA SILVA FERREIRA | B35: =IF(_xlfn.XLOOKUP(A35,PARAMETROS!A:A,PARAMETROS!B:B)=0,"",_xlfn.XLOOKUP(A35,PARAMETROS!A:A,PARAMETROS!B:B)) -> 012009006237 | C35: =IF(_xlfn.XLOOKUP(A35,PARAMETROS!A:A,PARAMETROS!C:C)=0,"",_xlfn.XLOOKUP(A35,PARAMETROS!A:A,PARAMETROS!C:C)) -> 12 | D35: =IF(_xlfn.XLOOKUP(A35,PARAMETROS!A:A,PARAMETROS!D:D)=0,"",_xlfn.XLOOKUP(A35,PARAMETROS!A:A,PARAMETROS!D:D)) -> 9 | E35: =IF(_xlfn.XLOOKUP('PREENCHIMENTO|LETIVAS'!A35,PARAMETROS!A:A,PARAMETROS!I:I)=0,"",_xlfn.XLOOKUP('PREENCHIMENTO|LETIVAS'!A35,PARAMETROS!A:A,PARAMETROS!I:I)) -> PROFESSOR REGENTE | F35: 51|2026 | G35: ESTENDIDA | H35: 3 - Terça | I35: 20:40 às 22:10 | J35: TEORIA DO URBANISMO | W35: =IF(I35<>"",2,0) -> 2
A36: LEONARDO DA SILVA FERREIRA | B36: =IF(_xlfn.XLOOKUP(A36,PARAMETROS!A:A,PARAMETROS!B:B)=0,"",_xlfn.XLOOKUP(A36,PARAMETROS!A:A,PARAMETROS!B:B)) -> 012009006237 | C36: =IF(_xlfn.XLOOKUP(A36,PARAMETROS!A:A,PARAMETROS!C:C)=0,"",_xlfn.XLOOKUP(A36,PARAMETROS!A:A,PARAMETROS!C:C)) -> 12 | D36: =IF(_xlfn.XLOOKUP(A36,PARAMETROS!A:A,PARAMETROS!D:D)=0,"",_xlfn.XLOOKUP(A36,PARAMETROS!A:A,PARAMETROS!D:D)) -> 9 | E36: =IF(_xlfn.XLOOKUP('PREENCHIMENTO|LETIVAS'!A36,PARAMETROS!A:A,PARAMETROS!I:I)=0,"",_xlfn.XLOOKUP('PREENCHIMENTO|LETIVAS'!A36,PARAMETROS!A:A,PARAMETROS!I:I)) -> PROFESSOR REGENTE | F36: 51|2026 | G36: ESTENDIDA | H36: 3 - Terça | I36: 19:00 às 20:30 | J36: TEORIA E HISTÓRIA DA ARQUITETURA, DO URBANISMO E DO PAISAGISMO | W36: =IF(I36<>"",2,0) -> 2
A37: LEONARDO DA SILVA FERREIRA | B37: =IF(_xlfn.XLOOKUP(A37,PARAMETROS!A:A,PARAMETROS!B:B)=0,"",_xlfn.XLOOKUP(A37,PARAMETROS!A:A,PARAMETROS!B:B)) -> 012009006237 | C37: =IF(_xlfn.XLOOKUP(A37,PARAMETROS!A:A,PARAMETROS!C:C)=0,"",_xlfn.XLOOKUP(A37,PARAMETROS!A:A,PARAMETROS!C:C)) -> 12 | D37: =IF(_xlfn.XLOOKUP(A37,PARAMETROS!A:A,PARAMETROS!D:D)=0,"",_xlfn.XLOOKUP(A37,PARAMETROS!A:A,PARAMETROS!D:D)) -> 9 | E37: =IF(_xlfn.XLOOKUP('PREENCHIMENTO|LETIVAS'!A37,PARAMETROS!A:A,PARAMETROS!I:I)=0,"",_xlfn.XLOOKUP('PREENCHIMENTO|LETIVAS'!A37,PARAMETROS!A:A,PARAMETROS!I:I)) -> PROFESSOR REGENTE | F37: 51|2026 | G37: 2 | H37: 4 - Quarta | I37: 20:40 às 22:10 | J37: PLANEJAMENTO E DESENVOLVIMENTO URBANO | W37: =IF(I37<>"",2,0) -> 2
A38: RAONY ROBSON RUIZ | B38: =IF(_xlfn.XLOOKUP(A38,PARAMETROS!A:A,PARAMETROS!B:B)=0,"",_xlfn.XLOOKUP(A38,PARAMETROS!A:A,PARAMETROS!B:B)) -> 012009006222 | C38: =IF(_xlfn.XLOOKUP(A38,PARAMETROS!A:A,PARAMETROS!C:C)=0,"",_xlfn.XLOOKUP(A38,PARAMETROS!A:A,PARAMETROS!C:C)) -> 12 | D38: =IF(_xlfn.XLOOKUP(A38,PARAMETROS!A:A,PARAMETROS!D:D)=0,"",_xlfn.XLOOKUP(A38,PARAMETROS!A:A,PARAMETROS!D:D)) -> 9 | E38: =IF(_xlfn.XLOOKUP('PREENCHIMENTO|LETIVAS'!A38,PARAMETROS!A:A,PARAMETROS!I:I)=0,"",_xlfn.XLOOKUP('PREENCHIMENTO|LETIVAS'!A38,PARAMETROS!A:A,PARAMETROS!I:I)) -> PROFESSOR REGENTE | F38: 51|2026 | G38: 1 | H38: 5 - Quinta | I38: 19:00 às 20:30 | J38: ARTE DIGITAL | W38: =IF(I38<>"",2,0) -> 2
A39: RAONY ROBSON RUIZ | B39: =IF(_xlfn.XLOOKUP(A39,PARAMETROS!A:A,PARAMETROS!B:B)=0,"",_xlfn.XLOOKUP(A39,PARAMETROS!A:A,PARAMETROS!B:B)) -> 012009006222 | C39: =IF(_xlfn.XLOOKUP(A39,PARAMETROS!A:A,PARAMETROS!C:C)=0,"",_xlfn.XLOOKUP(A39,PARAMETROS!A:A,PARAMETROS!C:C)) -> 12 | D39: =IF(_xlfn.XLOOKUP(A39,PARAMETROS!A:A,PARAMETROS!D:D)=0,"",_xlfn.XLOOKUP(A39,PARAMETROS!A:A,PARAMETROS!D:D)) -> 9 | E39: =IF(_xlfn.XLOOKUP('PREENCHIMENTO|LETIVAS'!A39,PARAMETROS!A:A,PARAMETROS!I:I)=0,"",_xlfn.XLOOKUP('PREENCHIMENTO|LETIVAS'!A39,PARAMETROS!A:A,PARAMETROS!I:I)) -> PROFESSOR REGENTE | F39: 51|2026 | G39: 2 | H39: 5 - Quinta | I39: 19:00 às 20:30 | J39: FUNDAMENTOS DA LINGUAGEM VISUAL | W39: =IF(I39<>"",2,0) -> 2
A40: TAYENE ELIZE MACAO | B40: =IF(_xlfn.XLOOKUP(A40,PARAMETROS!A:A,PARAMETROS!B:B)=0,"",_xlfn.XLOOKUP(A40,PARAMETROS!A:A,PARAMETROS!B:B)) -> 012009006225 | C40: =IF(_xlfn.XLOOKUP(A40,PARAMETROS!A:A,PARAMETROS!C:C)=0,"",_xlfn.XLOOKUP(A40,PARAMETROS!A:A,PARAMETROS!C:C)) -> 12 | D40: =IF(_xlfn.XLOOKUP(A40,PARAMETROS!A:A,PARAMETROS!D:D)=0,"",_xlfn.XLOOKUP(A40,PARAMETROS!A:A,PARAMETROS!D:D)) -> 9 | E40: =IF(_xlfn.XLOOKUP('PREENCHIMENTO|LETIVAS'!A40,PARAMETROS!A:A,PARAMETROS!I:I)=0,"",_xlfn.XLOOKUP('PREENCHIMENTO|LETIVAS'!A40,PARAMETROS!A:A,PARAMETROS!I:I)) -> PROFESSOR REGENTE | F40: 51|2026 | G40: 2 | H40: 5 - Quinta | I40: 20:40 às 22:10 | J40: LINGUAGEM POÉTICA DAS ARTES CÊNICAS | W40: =IF(I40<>"",2,0) -> 2
A41: TAYENE ELIZE MACAO | B41: =IF(_xlfn.XLOOKUP(A41,PARAMETROS!A:A,PARAMETROS!B:B)=0,"",_xlfn.XLOOKUP(A41,PARAMETROS!A:A,PARAMETROS!B:B)) -> 012009006225 | C41: =IF(_xlfn.XLOOKUP(A41,PARAMETROS!A:A,PARAMETROS!C:C)=0,"",_xlfn.XLOOKUP(A41,PARAMETROS!A:A,PARAMETROS!C:C)) -> 12 | D41: =IF(_xlfn.XLOOKUP(A41,PARAMETROS!A:A,PARAMETROS!D:D)=0,"",_xlfn.XLOOKUP(A41,PARAMETROS!A:A,PARAMETROS!D:D)) -> 9 | E41: =IF(_xlfn.XLOOKUP('PREENCHIMENTO|LETIVAS'!A41,PARAMETROS!A:A,PARAMETROS!I:I)=0,"",_xlfn.XLOOKUP('PREENCHIMENTO|LETIVAS'!A41,PARAMETROS!A:A,PARAMETROS!I:I)) -> PROFESSOR REGENTE | F41: 51|2026 | G41: 2 | H41: 5 - Quinta | I41: 19:00 às 20:30 | J41: CONTEXTO HISTÓRICO DO TEATRO | W41: =IF(I41<>"",2,0) -> 2
A42: TEREZA CRISTINA DE CARVALHO | B42: =IF(_xlfn.XLOOKUP(A42,PARAMETROS!A:A,PARAMETROS!B:B)=0,"",_xlfn.XLOOKUP(A42,PARAMETROS!A:A,PARAMETROS!B:B)) -> 012009003575 | C42: =IF(_xlfn.XLOOKUP(A42,PARAMETROS!A:A,PARAMETROS!C:C)=0,"",_xlfn.XLOOKUP(A42,PARAMETROS!A:A,PARAMETROS!C:C)) -> 20 | D42: =IF(_xlfn.XLOOKUP(A42,PARAMETROS!A:A,PARAMETROS!D:D)=0,"",_xlfn.XLOOKUP(A42,PARAMETROS!A:A,PARAMETROS!D:D)) -> 2 | E42: =IF(_xlfn.XLOOKUP('PREENCHIMENTO|LETIVAS'!A42,PARAMETROS!A:A,PARAMETROS!I:I)=0,"",_xlfn.XLOOKUP('PREENCHIMENTO|LETIVAS'!A42,PARAMETROS!A:A,PARAMETROS!I:I)) -> PROFESSOR DE ENSINO SUPERIOR EAD | F42: 51|2026 | G42: 2 | H42: 5 - Quinta | I42: 20:40 às 22:10 | J42: POLÍTICAS EDUCACIONAIS E ORGANIZAÇÃO DA EDUCAÇÃO BÁSICA | W42: =IF(I42<>"",2,0) -> 2
A43: RAQUEL DE ARAUJO BOMFIM GARCIA | B43: =IF(_xlfn.XLOOKUP(A43,PARAMETROS!A:A,PARAMETROS!B:B)=0,"",_xlfn.XLOOKUP(A43,PARAMETROS!A:A,PARAMETROS!B:B)) -> 012009003803 | C43: =IF(_xlfn.XLOOKUP(A43,PARAMETROS!A:A,PARAMETROS!C:C)=0,"",_xlfn.XLOOKUP(A43,PARAMETROS!A:A,PARAMETROS!C:C)) -> 20 | D43: =IF(_xlfn.XLOOKUP(A43,PARAMETROS!A:A,PARAMETROS!D:D)=0,"",_xlfn.XLOOKUP(A43,PARAMETROS!A:A,PARAMETROS!D:D)) -> 2 | E43: =IF(_xlfn.XLOOKUP('PREENCHIMENTO|LETIVAS'!A43,PARAMETROS!A:A,PARAMETROS!I:I)=0,"",_xlfn.XLOOKUP('PREENCHIMENTO|LETIVAS'!A43,PARAMETROS!A:A,PARAMETROS!I:I)) -> PROFESSOR DE ENSINO SUPERIOR EAD | F43: 51|2026 | G43: 2 | H43: 3 - Terça | I43: 19:00 às 20:30 | J43: PENSAMENTO CLÍNICO E POSTURA TERAPÊUTICA | W43: =IF(I43<>"",2,0) -> 2
A44: MARIANA ARDENGUE | B44: =IF(_xlfn.XLOOKUP(A44,PARAMETROS!A:A,PARAMETROS!B:B)=0,"",_xlfn.XLOOKUP(A44,PARAMETROS!A:A,PARAMETROS!B:B)) -> 012009004121 | C44: =IF(_xlfn.XLOOKUP(A44,PARAMETROS!A:A,PARAMETROS!C:C)=0,"",_xlfn.XLOOKUP(A44,PARAMETROS!A:A,PARAMETROS!C:C)) -> 20 | D44: =IF(_xlfn.XLOOKUP(A44,PARAMETROS!A:A,PARAMETROS!D:D)=0,"",_xlfn.XLOOKUP(A44,PARAMETROS!A:A,PARAMETROS!D:D)) -> 2 | E44: =IF(_xlfn.XLOOKUP('PREENCHIMENTO|LETIVAS'!A44,PARAMETROS!A:A,PARAMETROS!I:I)=0,"",_xlfn.XLOOKUP('PREENCHIMENTO|LETIVAS'!A44,PARAMETROS!A:A,PARAMETROS!I:I)) -> PROFESSOR DE ENSINO SUPERIOR EAD | F44: 51|2026 | G44: 1 | H44: 3 - Terça | I44: 19:00 às 20:30 | J44: ATIVIDADE FÍSICA E QUALIDADE DE VIDA | W44: =IF(I44<>"",2,0) -> 2
A45: ADRIANO RUY MATSUO | B45: =IF(_xlfn.XLOOKUP(A45,PARAMETROS!A:A,PARAMETROS!B:B)=0,"",_xlfn.XLOOKUP(A45,PARAMETROS!A:A,PARAMETROS!B:B)) -> 012009003801 | C45: =IF(_xlfn.XLOOKUP(A45,PARAMETROS!A:A,PARAMETROS!C:C)=0,"",_xlfn.XLOOKUP(A45,PARAMETROS!A:A,PARAMETROS!C:C)) -> 40 | D45: =IF(_xlfn.XLOOKUP(A45,PARAMETROS!A:A,PARAMETROS!D:D)=0,"",_xlfn.XLOOKUP(A45,PARAMETROS!A:A,PARAMETROS!D:D)) -> 4 | E45: =IF(_xlfn.XLOOKUP('PREENCHIMENTO|LETIVAS'!A45,PARAMETROS!A:A,PARAMETROS!I:I)=0,"",_xlfn.XLOOKUP('PREENCHIMENTO|LETIVAS'!A45,PARAMETROS!A:A,PARAMETROS!I:I)) -> PROFESSOR DE ENSINO SUPERIOR EAD | F45: 51|2026 | G45: 2 | H45: 3 - Terça | I45: 19:00 às 20:30 | J45: ATLETISMO | W45: =IF(I45<>"",2,0) -> 2
A46: ADRIANO RUY MATSUO | B46: =IF(_xlfn.XLOOKUP(A46,PARAMETROS!A:A,PARAMETROS!B:B)=0,"",_xlfn.XLOOKUP(A46,PARAMETROS!A:A,PARAMETROS!B:B)) -> 012009003801 | C46: =IF(_xlfn.XLOOKUP(A46,PARAMETROS!A:A,PARAMETROS!C:C)=0,"",_xlfn.XLOOKUP(A46,PARAMETROS!A:A,PARAMETROS!C:C)) -> 40 | D46: =IF(_xlfn.XLOOKUP(A46,PARAMETROS!A:A,PARAMETROS!D:D)=0,"",_xlfn.XLOOKUP(A46,PARAMETROS!A:A,PARAMETROS!D:D)) -> 4 | E46: =IF(_xlfn.XLOOKUP('PREENCHIMENTO|LETIVAS'!A46,PARAMETROS!A:A,PARAMETROS!I:I)=0,"",_xlfn.XLOOKUP('PREENCHIMENTO|LETIVAS'!A46,PARAMETROS!A:A,PARAMETROS!I:I)) -> PROFESSOR DE ENSINO SUPERIOR EAD | F46: 51|2026 | G46: 2 | H46: 3 - Terça | I46: 20:40 às 22:10 | J46: MUSCULAÇÃO E EXERCÍCIOS RESISTIDOS | W46: =IF(I46<>"",2,0) -> 2
...

Sheet PREENCHIMENTO|NÃO-LETIVAS
A1: - Considerar as atividades presentes na lista da coluna G; - Caso o total de horas dedicadas seja superior ao limite semanal de um professor, as linhas correspondentes ao nome dele ficarão vermelhas.
A8: LISTAS SUSPENSAS (Apenas Seleção)
A9: PROFESSOR(A) | B9: CHAPA | C9: CH SEMANAL | D9: CH NÃO-LETIVA | E9: CARGO | F9: MÓDULO | G9: ATIVIDADE | H9: CH DEDICADA | I9: OBSERVAÇÃO
